Exception on /user-projects/hamza [GET]
Traceback (most recent call last):
  File "C:\Program Files\Python312\Lib\site-packages\flask\app.py", line 1455, in wsgi_app
    response = self.full_dispatch_request()
               ^^^^^^^^^^^^^^^^^^^^^^^^^^^^
  File "C:\Program Files\Python312\Lib\site-packages\flask\app.py", line 869, in full_dispatch_request
    rv = self.handle_user_exception(e)
         ^^^^^^^^^^^^^^^^^^^^^^^^^^^^^
  File "C:\Users\mujaved21\AppData\Roaming\Python\Python312\site-packages\flask_cors\extension.py", line 176, in wrapped_function
    return cors_after_request(app.make_response(f(*args, **kwargs)))
                                                ^^^^^^^^^^^^^^^^^^
  File "C:\Program Files\Python312\Lib\site-packages\flask\app.py", line 867, in full_dispatch_request
    rv = self.dispatch_request()
         ^^^^^^^^^^^^^^^^^^^^^^^
  File "C:\Program Files\Python312\Lib\site-packages\flask\app.py", line 852, in dispatch_request
    return self.ensure_sync(self.view_functions[rule.endpoint])(**view_args)
           ^^^^^^^^^^^^^^^^^^^^^^^^^^^^^^^^^^^^^^^^^^^^^^^^^^^^^^^^^^^^^^^^^
  File "C:\Users\mujaved21\AppData\Roaming\Python\Python312\site-packages\flask_caching\__init__.py", line 399, in decorated_function
    rv = self._call_fn(f, *args, **kwargs)
         ^^^^^^^^^^^^^^^^^^^^^^^^^^^^^^^^^
  File "C:\Users\mujaved21\AppData\Roaming\Python\Python312\site-packages\flask_caching\__init__.py", line 175, in _call_fn
    return ensure_sync(fn)(*args, **kwargs)
           ^^^^^^^^^^^^^^^^^^^^^^^^^^^^^^^^
TypeError: fetch_user_projects() got an unexpected keyword argument 'username'
Exception on /user-projects/hamza [GET]
Traceback (most recent call last):
  File "C:\Program Files\Python312\Lib\site-packages\flask\app.py", line 1455, in wsgi_app
    response = self.full_dispatch_request()
               ^^^^^^^^^^^^^^^^^^^^^^^^^^^^
  File "C:\Program Files\Python312\Lib\site-packages\flask\app.py", line 869, in full_dispatch_request
    rv = self.handle_user_exception(e)
         ^^^^^^^^^^^^^^^^^^^^^^^^^^^^^
  File "C:\Users\mujaved21\AppData\Roaming\Python\Python312\site-packages\flask_cors\extension.py", line 176, in wrapped_function
    return cors_after_request(app.make_response(f(*args, **kwargs)))
                                                ^^^^^^^^^^^^^^^^^^
  File "C:\Program Files\Python312\Lib\site-packages\flask\app.py", line 867, in full_dispatch_request
    rv = self.dispatch_request()
         ^^^^^^^^^^^^^^^^^^^^^^^
  File "C:\Program Files\Python312\Lib\site-packages\flask\app.py", line 852, in dispatch_request
    return self.ensure_sync(self.view_functions[rule.endpoint])(**view_args)
           ^^^^^^^^^^^^^^^^^^^^^^^^^^^^^^^^^^^^^^^^^^^^^^^^^^^^^^^^^^^^^^^^^
  File "C:\Users\mujaved21\AppData\Roaming\Python\Python312\site-packages\flask_caching\__init__.py", line 399, in decorated_function
    rv = self._call_fn(f, *args, **kwargs)
         ^^^^^^^^^^^^^^^^^^^^^^^^^^^^^^^^^
  File "C:\Users\mujaved21\AppData\Roaming\Python\Python312\site-packages\flask_caching\__init__.py", line 175, in _call_fn
    return ensure_sync(fn)(*args, **kwargs)
           ^^^^^^^^^^^^^^^^^^^^^^^^^^^^^^^^
TypeError: fetch_user_projects() got an unexpected keyword argument 'username'
Exception on /user-projects/pertti@gmail.com [GET]
Traceback (most recent call last):
  File "C:\Program Files\Python312\Lib\site-packages\flask\app.py", line 1455, in wsgi_app
    response = self.full_dispatch_request()
               ^^^^^^^^^^^^^^^^^^^^^^^^^^^^
  File "C:\Program Files\Python312\Lib\site-packages\flask\app.py", line 869, in full_dispatch_request
    rv = self.handle_user_exception(e)
         ^^^^^^^^^^^^^^^^^^^^^^^^^^^^^
  File "C:\Users\mujaved21\AppData\Roaming\Python\Python312\site-packages\flask_cors\extension.py", line 176, in wrapped_function
    return cors_after_request(app.make_response(f(*args, **kwargs)))
                                                ^^^^^^^^^^^^^^^^^^
  File "C:\Program Files\Python312\Lib\site-packages\flask\app.py", line 867, in full_dispatch_request
    rv = self.dispatch_request()
         ^^^^^^^^^^^^^^^^^^^^^^^
  File "C:\Program Files\Python312\Lib\site-packages\flask\app.py", line 852, in dispatch_request
    return self.ensure_sync(self.view_functions[rule.endpoint])(**view_args)
           ^^^^^^^^^^^^^^^^^^^^^^^^^^^^^^^^^^^^^^^^^^^^^^^^^^^^^^^^^^^^^^^^^
  File "C:\Users\mujaved21\AppData\Roaming\Python\Python312\site-packages\flask_caching\__init__.py", line 399, in decorated_function
    rv = self._call_fn(f, *args, **kwargs)
         ^^^^^^^^^^^^^^^^^^^^^^^^^^^^^^^^^
  File "C:\Users\mujaved21\AppData\Roaming\Python\Python312\site-packages\flask_caching\__init__.py", line 175, in _call_fn
    return ensure_sync(fn)(*args, **kwargs)
           ^^^^^^^^^^^^^^^^^^^^^^^^^^^^^^^^
TypeError: fetch_user_projects() got an unexpected keyword argument 'username'
Exception on /user-projects/pertti@gmail.com [GET]
Traceback (most recent call last):
  File "C:\Program Files\Python312\Lib\site-packages\flask\app.py", line 1455, in wsgi_app
    response = self.full_dispatch_request()
               ^^^^^^^^^^^^^^^^^^^^^^^^^^^^
  File "C:\Program Files\Python312\Lib\site-packages\flask\app.py", line 869, in full_dispatch_request
    rv = self.handle_user_exception(e)
         ^^^^^^^^^^^^^^^^^^^^^^^^^^^^^
  File "C:\Users\mujaved21\AppData\Roaming\Python\Python312\site-packages\flask_cors\extension.py", line 176, in wrapped_function
    return cors_after_request(app.make_response(f(*args, **kwargs)))
                                                ^^^^^^^^^^^^^^^^^^
  File "C:\Program Files\Python312\Lib\site-packages\flask\app.py", line 867, in full_dispatch_request
    rv = self.dispatch_request()
         ^^^^^^^^^^^^^^^^^^^^^^^
  File "C:\Program Files\Python312\Lib\site-packages\flask\app.py", line 852, in dispatch_request
    return self.ensure_sync(self.view_functions[rule.endpoint])(**view_args)
           ^^^^^^^^^^^^^^^^^^^^^^^^^^^^^^^^^^^^^^^^^^^^^^^^^^^^^^^^^^^^^^^^^
  File "C:\Users\mujaved21\AppData\Roaming\Python\Python312\site-packages\flask_caching\__init__.py", line 399, in decorated_function
    rv = self._call_fn(f, *args, **kwargs)
         ^^^^^^^^^^^^^^^^^^^^^^^^^^^^^^^^^
  File "C:\Users\mujaved21\AppData\Roaming\Python\Python312\site-packages\flask_caching\__init__.py", line 175, in _call_fn
    return ensure_sync(fn)(*args, **kwargs)
           ^^^^^^^^^^^^^^^^^^^^^^^^^^^^^^^^
TypeError: fetch_user_projects() got an unexpected keyword argument 'username'
Exception on /user-projects/hamza [GET]
Traceback (most recent call last):
  File "C:\Program Files\Python312\Lib\site-packages\flask\app.py", line 1455, in wsgi_app
    response = self.full_dispatch_request()
               ^^^^^^^^^^^^^^^^^^^^^^^^^^^^
  File "C:\Program Files\Python312\Lib\site-packages\flask\app.py", line 869, in full_dispatch_request
    rv = self.handle_user_exception(e)
         ^^^^^^^^^^^^^^^^^^^^^^^^^^^^^
  File "C:\Users\mujaved21\AppData\Roaming\Python\Python312\site-packages\flask_cors\extension.py", line 176, in wrapped_function
    return cors_after_request(app.make_response(f(*args, **kwargs)))
                                                ^^^^^^^^^^^^^^^^^^
  File "C:\Program Files\Python312\Lib\site-packages\flask\app.py", line 867, in full_dispatch_request
    rv = self.dispatch_request()
         ^^^^^^^^^^^^^^^^^^^^^^^
  File "C:\Program Files\Python312\Lib\site-packages\flask\app.py", line 852, in dispatch_request
    return self.ensure_sync(self.view_functions[rule.endpoint])(**view_args)
           ^^^^^^^^^^^^^^^^^^^^^^^^^^^^^^^^^^^^^^^^^^^^^^^^^^^^^^^^^^^^^^^^^
  File "C:\Users\mujaved21\AppData\Roaming\Python\Python312\site-packages\flask_caching\__init__.py", line 399, in decorated_function
    rv = self._call_fn(f, *args, **kwargs)
         ^^^^^^^^^^^^^^^^^^^^^^^^^^^^^^^^^
  File "C:\Users\mujaved21\AppData\Roaming\Python\Python312\site-packages\flask_caching\__init__.py", line 175, in _call_fn
    return ensure_sync(fn)(*args, **kwargs)
           ^^^^^^^^^^^^^^^^^^^^^^^^^^^^^^^^
TypeError: fetch_user_projects() got an unexpected keyword argument 'username'
Exception on /user-projects/hamza [GET]
Traceback (most recent call last):
  File "C:\Program Files\Python312\Lib\site-packages\flask\app.py", line 1455, in wsgi_app
    response = self.full_dispatch_request()
               ^^^^^^^^^^^^^^^^^^^^^^^^^^^^
  File "C:\Program Files\Python312\Lib\site-packages\flask\app.py", line 869, in full_dispatch_request
    rv = self.handle_user_exception(e)
         ^^^^^^^^^^^^^^^^^^^^^^^^^^^^^
  File "C:\Users\mujaved21\AppData\Roaming\Python\Python312\site-packages\flask_cors\extension.py", line 176, in wrapped_function
    return cors_after_request(app.make_response(f(*args, **kwargs)))
                                                ^^^^^^^^^^^^^^^^^^
  File "C:\Program Files\Python312\Lib\site-packages\flask\app.py", line 867, in full_dispatch_request
    rv = self.dispatch_request()
         ^^^^^^^^^^^^^^^^^^^^^^^
  File "C:\Program Files\Python312\Lib\site-packages\flask\app.py", line 852, in dispatch_request
    return self.ensure_sync(self.view_functions[rule.endpoint])(**view_args)
           ^^^^^^^^^^^^^^^^^^^^^^^^^^^^^^^^^^^^^^^^^^^^^^^^^^^^^^^^^^^^^^^^^
  File "C:\Users\mujaved21\AppData\Roaming\Python\Python312\site-packages\flask_caching\__init__.py", line 399, in decorated_function
    rv = self._call_fn(f, *args, **kwargs)
         ^^^^^^^^^^^^^^^^^^^^^^^^^^^^^^^^^
  File "C:\Users\mujaved21\AppData\Roaming\Python\Python312\site-packages\flask_caching\__init__.py", line 175, in _call_fn
    return ensure_sync(fn)(*args, **kwargs)
           ^^^^^^^^^^^^^^^^^^^^^^^^^^^^^^^^
TypeError: fetch_user_projects() got an unexpected keyword argument 'username'
